Workbook

Sheet Posts
A1: Post ID | B1: Platform | C1: Date | D1: Content Type | E1: Post Text | F1: Likes | G1: Shares | H1: Comments | I1: Impressions | J1: Reach | K1: Clicks | L1: Hashtags Used | M1: Hashtags Used_01 | N1: Hashtags Used_02 | O1: Campaign_Name | P1: Engagement rate
A2: SP001 | B2: Instagram | C2: 45781 | D2: Text | E2: Discover fresh beats on Spotify! | F2: 2414 | G2: 245 | H2: 137 | I2: 21181 | J2: 45292 | K2: 133 | L2: #SoundtrackOfLife,#NowPlaying | M2: #SoundtrackOfLife | N2: #NowPlaying | O2: ChillVibes | P2: =(F2+G2+H2)/I2 -> 0.1320051
A3: SP002 | B3: Instagram | C3: 45689 | D3: Text | E3: Explore the latest podcasts now. | F3: 1934 | G3: 210 | H3: 393 | I3: 29129 | J3: 73287 | K3: 273 | L3: #DiscoverWeekly | M3: #DiscoverWeekly | O3: IndieWave | P3: =(F3+G3+H3)/I3 -> 0.087095335
A4: SP003 | B4: Twitter | C4: 45629 | D4: Story | E4: New music just dropped. Hit play! | F4: 3092 | G4: 177 | H4: 81 | I4: 47533 | J4: 29220 | K4: 121 | L4: #MusicForEveryone,#NowPlaying | M4: #MusicForEveryone | N4: #NowPlaying | O4: ChillVibes | P4: =(F4+G4+H4)/I4 -> 0.070477353
A5: SP004 | B5: Instagram | C5: 45629 | D5: Text | E5: Wrapped is here! Relive your top tracks | F5: 3173 | G5: 229 | H5: 197 | I5: 29604 | J5: 21809 | K5: 272 | L5: #SoundtrackOfLife,#NowPlaying | M5: #SoundtrackOfLife | N5: #NowPlaying | O5: ChillVibes | P5: =(F5+G5+H5)/I5 -> 0.12157141
A6: SP005 | B6: YouTube | C6: 45388 | D6: Text | E6: Music that moves you only on Spotify. | F6: 2748 | G6: 145 | H6: 315 | I6: 24401 | J6: 61182 | K6: 200 | L6: #DiscoverWeekly,#SpotifyWrapped | M6: #DiscoverWeekly | N6: #SpotifyWrapped | O6: IndieWave | P6: =(F6+G6+H6)/I6 -> 0.13147002
A7: SP006 | B7: YouTube | C7: 45456 | D7: Text | E7: What's your vibe today? #SpotifyHits | F7: 3882 | G7: 239 | H7: 275 | I7: 58748 | J7: 44646 | K7: 149 | L7: #DiscoverWeekly,#SpotifyWrapped | M7: #DiscoverWeekly | N7: #SpotifyWrapped | O7: IndieWave | P7: =(F7+G7+H7)/I7 -> 0.074828079
A8: SP007 | B8: Twitter | C8: 45645 | D8: Story | E8: Get into the groove with our new drop! | F8: 4674 | G8: 409 | H8: 327 | I8: 20756 | J8: 63599 | K8: 212 | L8: #SoundtrackOfLife,#NowPlaying | M8: #SoundtrackOfLife | N8: #NowPlaying | O8: ChillVibes | P8: =(F8+G8+H8)/I8 -> 0.26064752
A9: SP008 | B9: Twitter | C9: 45421 | D9: Story | E9: Wrapped is here! Relive your top tracks | F9: 1428 | G9: 347 | H9: 67 | I9: 21148 | J9: 19712 | K9: 120 | L9: #DiscoverWeekly,#MusicForEveryone | M9: #DiscoverWeekly | N9: #MusicForEveryone | O9: ChillVibes | P9: =(F9+G9+H9)/I9 -> 0.087100435
A10: SP009 | B10: Twitter | C10: 45823 | D10: Text | E10: Top trending tracks updated daily! | F10: 4432 | G10: 223 | H10: 299 | I10: 59016 | J10: 21742 | K10: 171 | L10: #NowPlaying | M10: #NowPlaying | O10: ChillVibes | P10: =(F10+G10+H10)/I10 -> 0.083943337
A11: SP010 | B11: Twitter | C11: 45630 | D11: Text | E11: Wrapped is here! Relive your top tracks | F11: 2357 | G11: 274 | H11: 172 | I11: 21566 | J11: 66829 | K11: 284 | L11: #NowPlaying | M11: #NowPlaying | O11: ChillVibes | P11: =(F11+G11+H11)/I11 -> 0.12997311
A12: SP011 | B12: Twitter | C12: 45357 | D12: Text | E12: Discover fresh beats on Spotify! | F12: 1971 | G12: 370 | H12: 306 | I12: 31316 | J12: 27897 | K12: 88 | L12: #SoundtrackOfLife | M12: #SoundtrackOfLife | O12: IndieWave | P12: =(F12+G12+H12)/I12 -> 0.084525482
A13: SP012 | B13: Instagram | C13: 45426 | D13: Text | E13: Discover fresh beats on Spotify! | F13: 1485 | G13: 353 | H13: 244 | I13: 38419 | J13: 38556 | K13: 86 | L13: #SoundtrackOfLife,#NowPlaying | M13: #SoundtrackOfLife | N13: #NowPlaying | O13: ChillVibes | P13: =(F13+G13+H13)/I13 -> 0.054191936
A14: SP013 | B14: Twitter | C14: 45826 | D14: Story | E14: Discover fresh beats on Spotify! | F14: 3956 | G14: 319 | H14: 61 | I14: 58162 | J14: 28720 | K14: 213 | L14: #MusicForEveryone,#NowPlaying | M14: #MusicForEveryone | N14: #NowPlaying | O14: ChillVibes | P14: =(F14+G14+H14)/I14 -> 0.074550394
A15: SP014 | B15: Twitter | C15: 45573 | D15: Text | E15: From pop to podcasts, its all here. | F15: 2460 | G15: 409 | H15: 253 | I15: 36702 | J15: 46122 | K15: 264 | L15: #NowPlaying | M15: #NowPlaying | O15: ChillVibes | P15: =(F15+G15+H15)/I15 -> 0.085063484
A16: SP015 | B16: Twitter | C16: 45418 | D16: Text | E16: Your weekend playlist is waiting. | F16: 3476 | G16: 355 | H16: 396 | I16: 37492 | J16: 27285 | K16: 179 | L16: #NowPlaying | M16: #NowPlaying | O16: ChillVibes | P16: =(F16+G16+H16)/I16 -> 0.11274405
A17: SP016 | B17: Twitter | C17: 45655 | D17: Story | E17: New music just dropped. Hit play! | F17: 4049 | G17: 377 | H17: 94 | I17: 48182 | J17: 42875 | K17: 172 | L17: #MusicForEveryone,#NowPlaying | M17: #MusicForEveryone | N17: #NowPlaying | O17: ChillVibes | P17: =(F17+G17+H17)/I17 -> 0.093810967
A18: SP017 | B18: Twitter | C18: 45453 | D18: Text | E18: What's your vibe today? #SpotifyHits | F18: 1514 | G18: 164 | H18: 275 | I18: 41364 | J18: 44389 | K18: 83 | L18: #NowPlaying | M18: #NowPlaying | O18: ChillVibes | P18: =(F18+G18+H18)/I18 -> 0.04721497
A19: SP018 | B19: Instagram | C19: 45325 | D19: Story | E19: Music that moves you only on Spotify. | F19: 4281 | G19: 101 | H19: 163 | I19: 32278 | J19: 53382 | K19: 235 | L19: #NowPlaying | M19: #NowPlaying | O19: Wrapped2024 | P19: =(F19+G19+H19)/I19 -> 0.14080798
A20: SP019 | B20: YouTube | C20: 45458 | D20: Reel | E20: Get into the groove with our new drop! | F20: 1751 | G20: 143 | H20: 151 | I20: 31826 | J20: 47729 | K20: 95 | L20: #DiscoverWeekly,#SoundtrackOfLife | M20: #DiscoverWeekly | N20: #SoundtrackOfLife | O20: SummerBeats | P20: =(F20+G20+H20)/I20 -> 0.06425564
A21: SP020 | B21: Instagram | C21: 45478 | D21: Text | E21: Your weekend playlist is waiting. | F21: 3753 | G21: 411 | H21: 308 | I21: 29138 | J21: 27678 | K21: 90 | L21: #DiscoverWeekly | M21: #DiscoverWeekly | O21: IndieWave | P21: =(F21+G21+H21)/I21 -> 0.15347656
A22: SP021 | B22: Instagram | C22: 45603 | D22: Story | E22: Wrapped is here! Relive your top tracks | F22: 1678 | G22: 423 | H22: 323 | I22: 55668 | J22: 37945 | K22: 230 | L22: #NowPlaying | M22: #NowPlaying | O22: Wrapped2024 | P22: =(F22+G22+H22)/I22 -> 0.043543867
A23: SP022 | B23: Instagram | C23: 45823 | D23: Text | E23: What's your vibe today? #SpotifyHits | F23: 4896 | G23: 466 | H23: 233 | I23: 28621 | J23: 34270 | K23: 84 | L23: #SoundtrackOfLife,#NowPlaying | M23: #SoundtrackOfLife | N23: #NowPlaying | O23: ChillVibes | P23: =(F23+G23+H23)/I23 -> 0.19548583
A24: SP023 | B24: YouTube | C24: 45452 | D24: Reel | E24: From pop to podcasts, its all here. | F24: 2786 | G24: 368 | H24: 208 | I24: 42000 | J24: 39967 | K24: 103 | L24: #DiscoverWeekly,#SoundtrackOfLife | M24: #DiscoverWeekly | N24: #SoundtrackOfLife | O24: SummerBeats | P24: =(F24+G24+H24)/I24 -> 0.080047619
A25: SP024 | B25: Twitter | C25: 45583 | D25: Text | E25: New music just dropped. Hit play! | F25: 2607 | G25: 379 | H25: 180 | I25: 28712 | J25: 61620 | K25: 174 | L25: #SoundtrackOfLife | M25: #SoundtrackOfLife | O25: IndieWave | P25: =(F25+G25+H25)/I25 -> 0.11026748
A26: SP025 | B26: YouTube | C26: 45575 | D26: Reel | E26: From pop to podcasts, its all here. | F26: 4013 | G26: 320 | H26: 92 | I26: 54605 | J26: 60169 | K26: 232 | L26: #DiscoverWeekly,#SoundtrackOfLife | M26: #DiscoverWeekly | N26: #SoundtrackOfLife | O26: SummerBeats | P26: =(F26+G26+H26)/I26 -> 0.081036535
A27: SP026 | B27: Twitter | C27: 45791 | D27: Story | E27: From pop to podcasts, its all here. | F27: 2707 | G27: 103 | H27: 51 | I27: 55302 | J27: 18801 | K27: 147 | L27: #DiscoverWeekly,#MusicForEveryone | M27: #DiscoverWeekly | N27: #MusicForEveryone | O27: ChillVibes | P27: =(F27+G27+H27)/I27 -> 0.051734114
A28: SP027 | B28: Instagram | C28: 45625 | D28: Text | E28: What's your vibe today? #SpotifyHits | F28: 2824 | G28: 425 | H28: 274 | I28: 31004 | J28: 53488 | K28: 268 | L28: #SoundtrackOfLife,#NowPlaying | M28: #SoundtrackOfLife | N28: #NowPlaying | O28: ChillVibes | P28: =(F28+G28+H28)/I28 -> 0.1136305
A29: SP028 | B29: YouTube | C29: 45356 | D29: Reel | E29: Explore the latest podcasts now. | F29: 3558 | G29: 314 | H29: 199 | I29: 49612 | J29: 53929 | K29: 206 | L29: #DiscoverWeekly,#SoundtrackOfLife | M29: #DiscoverWeekly | N29: #SoundtrackOfLife | O29: SummerBeats | P29: =(F29+G29+H29)/I29 -> 0.08205676
A30: SP029 | B30: Twitter | C30: 45734 | D30: Story | E30: Explore the latest podcasts now. | F30: 3418 | G30: 188 | H30: 387 | I30: 57431 | J30: 36933 | K30: 202 | L30: #MusicForEveryone,#NowPlaying | M30: #MusicForEveryone | N30: #NowPlaying | O30: ChillVibes | P30: =(F30+G30+H30)/I30 -> 0.069526911
A31: SP030 | B31: Twitter | C31: 45773 | D31: Text | E31: Discover fresh beats on Spotify! | F31: 2411 | G31: 194 | H31: 168 | I31: 26665 | J31: 71699 | K31: 197 | L31: #NowPlaying | M31: #NowPlaying | O31: ChillVibes | P31: =(F31+G31+H31)/I31 -> 0.103994
A32: SP031 | B32: Instagram | C32: 45658 | D32: Text | E32: New music just dropped. Hit play! | F32: 4036 | G32: 112 | H32: 382 | I32: 56284 | J32: 29440 | K32: 279 | L32: #SoundtrackOfLife,#NowPlaying | M32: #SoundtrackOfLife | N32: #NowPlaying | O32: ChillVibes | P32: =(F32+G32+H32)/I32 -> 0.080484685
A33: SP032 | B33: Twitter | C33: 45419 | D33: Story | E33: Explore the latest podcasts now. | F33: 2776 | G33: 307 | H33: 178 | I33: 43365 | J33: 48408 | K33: 138 | L33: #SoundtrackOfLife,#NowPlaying | M33: #SoundtrackOfLife | N33: #NowPlaying | O33: ChillVibes | P33: =(F33+G33+H33)/I33 -> 0.075198893
A34: SP033 | B34: Twitter | C34: 45574 | D34: Story | E34: Discover fresh beats on Spotify! | F34: 4929 | G34: 182 | H34: 95 | I34: 32181 | J34: 31084 | K34: 289 | L34: #DiscoverWeekly,#MusicForEveryone | M34: #DiscoverWeekly | N34: #MusicForEveryone | O34: ChillVibes | P34: =(F34+G34+H34)/I34 -> 0.16177247
A35: SP034 | B35: Instagram | C35: 45666 | D35: Text | E35: New music just dropped. Hit play! | F35: 1015 | G35: 366 | H35: 308 | I35: 38127 | J35: 63790 | K35: 287 | L35: #SoundtrackOfLife,#NowPlaying | M35: #SoundtrackOfLife | N35: #NowPlaying | O35: ChillVibes | P35: =(F35+G35+H35)/I35 -> 0.044299315
A36: SP035 | B36: Twitter | C36: 45785 | D36: Story | E36: Your weekend playlist is waiting. | F36: 3316 | G36: 332 | H36: 268 | I36: 40095 | J36: 36913 | K36: 265 | L36: #MusicForEveryone,#NowPlaying | M36: #MusicForEveryone | N36: #NowPlaying | O36: ChillVibes | P36: =(F36+G36+H36)/I36 -> 0.097668038
A37: SP036 | B37: Instagram | C37: 45416 | D37: Text | E37: Wrapped is here! Relive your top tracks | F37: 2274 | G37: 243 | H37: 222 | I37: 43066 | J37: 59174 | K37: 80 | L37: #DiscoverWeekly | M37: #DiscoverWeekly | O37: IndieWave | P37: =(F37+G37+H37)/I37 -> 0.063600056
A38: SP037 | B38: Twitter | C38: 45804 | D38: Story | E38: Explore the latest podcasts now. | F38: 4095 | G38: 385 | H38: 400 | I38: 45300 | J38: 31795 | K38: 80 | L38: #MusicForEveryone,#NowPlaying | M38: #MusicForEveryone | N38: #NowPlaying | O38: ChillVibes | P38: =(F38+G38+H38)/I38 -> 0.10772627
A39: SP038 | B39: Instagram | C39: 45545 | D39: Story | E39: New music just dropped. Hit play! | F39: 1230 | G39: 309 | H39: 207 | I39: 44629 | J39: 40699 | K39: 195 | L39: #NowPlaying | M39: #NowPlaying | O39: Wrapped2024 | P39: =(F39+G39+H39)/I39 -> 0.039122544
A40: SP039 | B40: Instagram | C40: 45621 | D40: Text | E40: From pop to podcasts, its all here. | F40: 1341 | G40: 472 | H40: 238 | I40: 51386 | J40: 51706 | K40: 133 | L40: #DiscoverWeekly | M40: #DiscoverWeekly | O40: IndieWave | P40: =(F40+G40+H40)/I40 -> 0.039913595
...

Sheet Engagement Summary
A1: Week_Start_Date | B1: Platform | C1: New_Followers | D1: Unfollows | E1: Total_Followers | F1: Engagement_Rate | G1: Ad_Spend | H1: Growth rate per post | I1: Net Gain | J1: Week Date | K1: Sum of Net Gain Per Week
A2: 45446 | B2: Instagram | C2: 1402 | D2: 68 | E2: 124562 | F2: 9.92 | G2: 23125 | H2: =(C2-D2)/E2 -> 0.010709526 | I2: =C2-D2 -> 1334 | J2: 45446 | K2: 3419
A3: 45446 | B3: Twitter | C3: 995 | D3: 86 | E3: 227958 | F3: 8.05 | G3: 22788 | H3: =(C3-D3)/E3 -> 0.0039875767 | I3: =C3-D3 -> 909 | J3: 45453 | K3: 2777
A4: 45446 | B4: YouTube | C4: 1472 | D4: 296 | E4: 370242 | F4: 7.72 | G4: 7810 | H4: =(C4-D4)/E4 -> 0.0031763009 | I4: =C4-D4 -> 1176 | J4: 45460 | K4: 3175
A5: 45453 | B5: Instagram | C5: 1018 | D5: 90 | E5: 92474 | F5: 9.4 | G5: 11966 | H5: =(C5-D5)/E5 -> 0.010035253 | I5: =C5-D5 -> 928 | J5: 45467 | K5: 2433
A6: 45453 | B6: Twitter | C6: 1461 | D6: 64 | E6: 328902 | F6: 9.02 | G6: 26298 | H6: =(C6-D6)/E6 -> 0.0042474658 | I6: =C6-D6 -> 1397 | J6: 45474 | K6: 2426
A7: 45453 | B7: YouTube | C7: 545 | D7: 93 | E7: 391621 | F7: 9.96 | G7: 22029 | H7: =(C7-D7)/E7 -> 0.0011541771 | I7: =C7-D7 -> 452 | J7: 45481 | K7: 3155
A8: 45460 | B8: Instagram | C8: 881 | D8: 291 | E8: 95885 | F8: 5.29 | G8: 12391 | H8: =(C8-D8)/E8 -> 0.0061532044 | I8: =C8-D8 -> 590 | J8: 45488 | K8: 2369
A9: 45460 | B9: Twitter | C9: 1414 | D9: 131 | E9: 245947 | F9: 8.3 | G9: 14477 | H9: =(C9-D9)/E9 -> 0.005216571 | I9: =C9-D9 -> 1283 | J9: 45495 | K9: 2281
A10: 45460 | B10: YouTube | C10: 1472 | D10: 170 | E10: 250428 | F10: 4.66 | G10: 25040 | H10: =(C10-D10)/E10 -> 0.0051990991 | I10: =C10-D10 -> 1302 | J10: 45502 | K10: 2132
A11: 45467 | B11: Instagram | C11: 809 | D11: 197 | E11: 87186 | F11: 9.48 | G11: 22619 | H11: =(C11-D11)/E11 -> 0.0070194756 | I11: =C11-D11 -> 612 | J11: 45509 | K11: 2693
A12: 45467 | B12: Twitter | C12: 1371 | D12: 250 | E12: 128620 | F12: 7.11 | G12: 12399 | H12: =(C12-D12)/E12 -> 0.0087155963 | I12: =C12-D12 -> 1121 | J12: 45516 | K12: 3072
A13: 45467 | B13: YouTube | C13: 844 | D13: 144 | E13: 126015 | F13: 9.65 | G13: 22456 | H13: =(C13-D13)/E13 -> 0.0055548943 | I13: =C13-D13 -> 700 | J13: 45523 | K13: 2300
... A68: 45600 | B68: Instagram | C68: 1437 | D68: 235 | E68: 326791 | F68: 4.06 | G68: 14563 | H68: =(C68-D68)/E68 -> 0.0036781919 | I68: =C68-D68 -> 1202 | J68: 45908 | K68: 1436
A69: 45600 | B69: Twitter | C69: 1463 | D69: 73 | E69: 348877 | F69: 9.91 | G69: 26273 | H69: =(C69-D69)/E69 -> 0.0039842122 | I69: =C69-D69 -> 1390 | J69: Grand Total | K69: 161588
A70: 45600 | B70: YouTube | C70: 1208 | D70: 224 | E70: 122730 | F70: 8.72 | G70: 10858 | H70: =(C70-D70)/E70 -> 0.0080175996 | I70: =C70-D70 -> 984
A71: 45607 | B71: Instagram | C71: 1391 | D71: 187 | E71: 306508 | F71: 8.38 | G71: 25038 | H71: =(C71-D71)/E71 -> 0.0039281193 | I71: =C71-D71 -> 1204
A72: 45607 | B72: Twitter | C72: 655 | D72: 123 | E72: 202472 | F72: 7.56 | G72: 9092 | H72: =(C72-D72)/E72 -> 0.0026275238 | I72: =C72-D72 -> 532
A73: 45607 | B73: YouTube | C73: 1148 | D73: 90 | E73: 227249 | F73: 7.24 | G73: 17662 | H73: =(C73-D73)/E73 -> 0.0046556861 | I73: =C73-D73 -> 1058
A74: 45614 | B74: Instagram | C74: 946 | D74: 270 | E74: 246567 | F74: 4.53 | G74: 5924 | H74: =(C74-D74)/E74 -> 0.0027416483 | I74: =C74-D74 -> 676
A75: 45614 | B75: Twitter | C75: 791 | D75: 214 | E75: 114738 | F75: 6.62 | G75: 25347 | H75: =(C75-D75)/E75 -> 0.0050288483 | I75: =C75-D75 -> 577
A76: 45614 | B76: YouTube | C76: 793 | D76: 111 | E76: 333500 | F76: 6.36 | G76: 8910 | H76: =(C76-D76)/E76 -> 0.0020449775 | I76: =C76-D76 -> 682
A77: 45621 | B77: Instagram | C77: 663 | D77: 213 | E77: 352677 | F77: 9 | G77: 20438 | H77: =(C77-D77)/E77 -> 0.0012759551 | I77: =C77-D77 -> 450
A78: 45621 | B78: Twitter | C78: 954 | D78: 271 | E78: 160936 | F78: 8.83 | G78: 8760 | H78: =(C78-D78)/E78 -> 0.0042439231 | I78: =C78-D78 -> 683
A79: 45621 | B79: YouTube | C79: 1313 | D79: 159 | E79: 197183 | F79: 9.71 | G79: 6625 | H79: =(C79-D79)/E79 -> 0.0058524315 | I79: =C79-D79 -> 1154
A80: 45628 | B80: Instagram | C80: 895 | D80: 87 | E80: 171271 | F80: 6.68 | G80: 23329 | H80: =(C80-D80)/E80 -> 0.0047176697 | I80: =C80-D80 -> 808
A81: 45628 | B81: Twitter | C81: 1027 | D81: 156 | E81: 111293 | F81: 5.51 | G81: 7299 | H81: =(C81-D81)/E81 -> 0.0078261885 | I81: =C81-D81 -> 871
... A201: 45908 | B201: Twitter | C201: 860 | D201: 244 | E201: 348686 | F201: 5.12 | G201: 11418 | H201: =(C201-D201)/E201 -> 0.0017666324 | I201: =C201-D201 -> 616

Sheet Campaign Metadata
A1: Campaign_Name | B1: Start_Date | C1: End_Date | D1: Objective | E1: Total_Budget | F1: Target_Platforms | G1: Primary_Hashtags | H1: Primary_Hashtags01 | I1: Primary_Hashtags_02 | K1: Engagement before | L1: Engagement during | M1: Uplift
A2: SummerBeats | B2: 45458 | C2: 45488 | D2: Brand Awareness | E2: 175000 | F2: Instagram,YouTube | G2: #SpotifyWrapped,#MusicForEveryone | H2: #SpotifyWrapped | I2: #MusicForEveryone | K2: =AVERAGEIFS(Posts!P:P, Posts!C:C, "<"&B2) -> 0.08761517 | L2: =AVERAGEIFS(Posts!H:H, Posts!C:C, ">="&B2, Posts!C:C, "<="&C2) -> 197.83333 | M2: =IF(K2=0,"",((L2-K2)/K2)*100) -> 225698.04
A3: Wrapped2024 | B3: 45627 | C3: 45657 | D3: Engagement | E3: 225000 | F3: Twitter,YouTube | G3: #SpotifyWrapped,#NowPlaying | H3: #SpotifyWrapped | I3: #NowPlaying | K3: =AVERAGEIFS(Posts!P:P, Posts!C:C, "<"&B3) -> 0.090137338 | L3: =AVERAGEIFS(Posts!H:H, Posts!C:C, ">="&B3, Posts!C:C, "<="&C3) -> 226.11111 | M3: =IF(K3=0,"",((L3-K3)/K3)*100) -> 250751.77
A4: ChillVibes | B4: 45667 | C4: 45698 | D4: Product Launch | E4: 200000 | F4: Instagram,Twitter | G4: #ChillVibes,#SoundtrackOfLife | H4: #ChillVibes | I4: #SoundtrackOfLife | K4: =AVERAGEIFS(Posts!P:P, Posts!C:C, "<"&B4) -> 0.090969117 | L4: =AVERAGEIFS(Posts!H:H, Posts!C:C, ">="&B4, Posts!C:C, "<="&C4) -> 196.09091 | M4: =IF(K4=0,"",((L4-K4)/K4)*100) -> 215457.67
A5: IndieWave | B5: 45717 | C5: 45747 | D5: Traffic | E5: 160000 | F5: Facebook,Instagram | G5: #DiscoverWeekly,#IndieWave | H5: #DiscoverWeekly | I5: #IndieWave | K5: =AVERAGEIFS(Posts!P:P, Posts!C:C, "<"&B5) -> 0.092816605 | L5: =AVERAGEIFS(Posts!H:H, Posts!C:C, ">="&B5, Posts!C:C, "<="&C5) -> 250.69231 | M5: =IF(K5=0,"",((L5-K5)/K5)*100) -> 269994.24
K7: Engagement Uplift

Sheet Engagement Analysis
A1: Total enagement | B1: Engagement rate | D1: Engagement rate per platform | G1: Top 10 post | H1: Top 10 Post By Engagment Rate | X1: Top 15 Highest Reach | Y1: Top 15 performing hashtags | AA1: Hashtags | AB1: Sum of Clicks | AD1: Hashtags | AE1: Sum of Clicks
A2: =(Posts!F2+Posts!G2+Posts!H2) -> 2796 | B2: =('Engagement Analysis'!A2)/Posts!I2 -> 0.1320051 | D2: Avg rate for Instagram | E2: =AVERAGEIF(Posts!B:B,"Instagram",'Engagement Analysis'!B:B) -> 0.09079483 | G2: =LARGE('Engagement Analysis'!B:B,1) -> 0.26064752 | H2: =INDEX(Posts!E:E, MATCH(G2, 'Engagement Analysis'!B:B, 0)) -> Get into the groove with our new drop! | M2: Distribution of Total Interaction of the user by Content type & Platform | X2: =LARGE(Posts!$J$2:$J$301,1) -> 74761 | Y2: =INDEX(Posts!$L$2:$L$301, MATCH(X2, $X$2:$X$301, 0)) -> #SoundtrackOfLife,#NowPlaying | AA2: #DiscoverWeekly | AB2: 25632 | AD2: #MusicForEveryone | AE2: 6621
A3: =(Posts!F3+Posts!G3+Posts!H3) -> 2537 | B3: =('Engagement Analysis'!A3)/Posts!I3 -> 0.087095335 | D3: Avg rate for Twitter | E3: =AVERAGEIF(Posts!B:B,"twitter",'Engagement Analysis'!B:B) -> 0.096034606 | G3: =LARGE('Engagement Analysis'!B:B,2) -> 0.23193025 | H3: =INDEX(Posts!E:E, MATCH(G3, 'Engagement Analysis'!B:B, 0)) -> New music just dropped. Hit play! | X3: =LARGE(Posts!$J$2:$J$301,2) -> 74590 | Y3: =INDEX(Posts!$L$2:$L$301, MATCH(X3, $X$2:$X$301, 0)) -> #DiscoverWeekly | AA3: #MusicForEveryone | AB3: 5672 | AD3: #NowPlaying | AE3: 15830
A4: =(Posts!F4+Posts!G4+Posts!H4) -> 3350 | B4: =('Engagement Analysis'!A4)/Posts!I4 -> 0.070477353 | D4: Avg rate for YouTube | E4: =AVERAGEIF(Posts!B:B,"YouTube",'Engagement Analysis'!B:B) -> 0.088108119 | G4: =LARGE('Engagement Analysis'!B:B,3) -> 0.22967525 | H4: =INDEX(Posts!E:E, MATCH(G4, 'Engagement Analysis'!B:B, 0)) -> Explore the latest podcasts now. | K4: Instagram | N4: Twitter | Q4: YouTube | T4: Total Sum of Likes | U4: Total Sum of Shares | V4: Total Sum of Comments | X4: =LARGE(Posts!$J$2:$J$301,3) -> 74305 | Y4: =INDEX(Posts!$L$2:$L$301, MATCH(X4, $X$2:$X$301, 0)) -> #MusicForEveryone,#NowPlaying | AA4: #NowPlaying | AB4: 10871 | AD4: #SoundtrackOfLife | AE4: 5557
A5: =(Posts!F5+Posts!G5+Posts!H5) -> 3599 | B5: =('Engagement Analysis'!A5)/Posts!I5 -> 0.12157141 | G5: =LARGE('Engagement Analysis'!B:B,4) -> 0.2044586 | H5: =INDEX(Posts!E:E, MATCH(G5, 'Engagement Analysis'!B:B, 0)) -> New music just dropped. Hit play! | J5: Content type | K5: Sum of Likes | L5: Sum of Shares | M5: Sum of Comments | N5: Sum of Likes | O5: Sum of Shares | P5: Sum of Comments | Q5: Sum of Likes | R5: Sum of Shares | S5: Sum of Comments | X5: =LARGE(Posts!$J$2:$J$301,4) -> 74048 | Y5: =INDEX(Posts!$L$2:$L$301, MATCH(X5, $X$2:$X$301, 0)) -> #SoundtrackOfLife,#NowPlaying | AA5: #SoundtrackOfLife | AB5: 15421 | AD5: #SpotifyWrapped | AE5: 7088
A6: =(Posts!F6+Posts!G6+Posts!H6) -> 3208 | B6: =('Engagement Analysis'!A6)/Posts!I6 -> 0.13147002 | D6: Formula = AVERAGEIF(range, criteria, [average_range]) | G6: =LARGE('Engagement Analysis'!B:B,5) -> 0.20241061 | H6: =INDEX(Posts!E:E, MATCH(G6, 'Engagement Analysis'!B:B, 0)) -> Discover fresh beats on Spotify! | J6: Reel | Q6: 89871 | R6: 9086 | S6: 6826 | T6: 89871 | U6: 9086 | V6: 6826 | X6: =LARGE(Posts!$J$2:$J$301,5) -> 73793 | Y6: =INDEX(Posts!$L$2:$L$301, MATCH(X6, $X$2:$X$301, 0)) -> #DiscoverWeekly,#SpotifyWrapped | AA6: Grand Total | AB6: 57596 | AD6: Grand Total | AE6: 35096
A7: =(Posts!F7+Posts!G7+Posts!H7) -> 4396 | B7: =('Engagement Analysis'!A7)/Posts!I7 -> 0.074828079 | G7: =LARGE('Engagement Analysis'!B:B,6) -> 0.19548583 | H7: =INDEX(Posts!E:E, MATCH(G7, 'Engagement Analysis'!B:B, 0)) -> What's your vibe today? #SpotifyHits | J7: Story | K7: 61815 | L7: 7993 | M7: 5656 | N7: 272103 | O7: 26494 | P7: 18442 | T7: 333918 | U7: 34487 | V7: 24098 | X7: =LARGE(Posts!$J$2:$J$301,6) -> 73593 | Y7: =INDEX(Posts!$L$2:$L$301, MATCH(X7, $X$2:$X$301, 0)) -> #DiscoverWeekly,#SpotifyWrapped | AA7: Avg Clicks as per Separate Hastags Column
A8: =(Posts!F8+Posts!G8+Posts!H8) -> 5410 | B8: =('Engagement Analysis'!A8)/Posts!I8 -> 0.26064752 | G8: =LARGE('Engagement Analysis'!B:B,7) -> 0.19390492 | H8: =INDEX(Posts!E:E, MATCH(G8, 'Engagement Analysis'!B:B, 0)) -> From pop to podcasts, its all here. | J8: Text | K8: 189658 | L8: 21292 | M8: 15162 | N8: 178192 | O8: 19004 | P8: 13135 | Q8: 105536 | R8: 9532 | S8: 7845 | T8: 473386 | U8: 49828 | V8: 36142 | X8: =LARGE(Posts!$J$2:$J$301,7) -> 73503 | Y8: =INDEX(Posts!$L$2:$L$301, MATCH(X8, $X$2:$X$301, 0)) -> #SoundtrackOfLife,#NowPlaying
A9: =(Posts!F9+Posts!G9+Posts!H9) -> 1842 | B9: =('Engagement Analysis'!A9)/Posts!I9 -> 0.087100435 | D9: Engagement Per Platform | G9: =LARGE('Engagement Analysis'!B:B,8) -> 0.19261223 | H9: =INDEX(Posts!E:E, MATCH(G9, 'Engagement Analysis'!B:B, 0)) -> Wrapped is here! Relive your top tracks | J9: Grand Total | K9: 251473 | L9: 29285 | M9: 20818 | N9: 450295 | O9: 45498 | P9: 31577 | Q9: 195407 | R9: 18618 | S9: 14671 | T9: 897175 | U9: 93401 | V9: 67066 | X9: =LARGE(Posts!$J$2:$J$301,8) -> 73287 | Y9: =INDEX(Posts!$L$2:$L$301, MATCH(X9, $X$2:$X$301, 0)) -> #DiscoverWeekly,#MusicForEveryone | AA9: Average Click Per hastag
A10: =(Posts!F10+Posts!G10+Posts!H10) -> 4954 | B10: =('Engagement Analysis'!A10)/Posts!I10 -> 0.083943337 | G10: =LARGE('Engagement Analysis'!B:B,9) -> 0.18723442 | H10: =INDEX(Posts!E:E, MATCH(G10, 'Engagement Analysis'!B:B, 0)) -> Top trending tracks updated daily! | X10: =LARGE(Posts!$J$2:$J$301,9) -> 73144 | Y10: =INDEX(Posts!$L$2:$L$301, MATCH(X10, $X$2:$X$301, 0)) -> #NowPlaying | AA10: #DiscoverWeekly | AB10: 25632
A11: =(Posts!F11+Posts!G11+Posts!H11) -> 2803 | B11: =('Engagement Analysis'!A11)/Posts!I11 -> 0.12997311 | G11: =LARGE('Engagement Analysis'!B:B,10) -> 0.18517979 | H11: =INDEX(Posts!E:E, MATCH(G11, 'Engagement Analysis'!B:B, 0)) -> Music that moves you only on Spotify. | X11: =LARGE(Posts!$J$2:$J$301,10) -> 72934 | Y11: =INDEX(Posts!$L$2:$L$301, MATCH(X11, $X$2:$X$301, 0)) -> #NowPlaying | AA11: #MusicForEveryone | AB11: 12293
A12: =(Posts!F12+Posts!G12+Posts!H12) -> 2647 | B12: =('Engagement Analysis'!A12)/Posts!I12 -> 0.084525482 | N12: Distribution of Total Interaction of the user by Content type & Platform | X12: =LARGE(Posts!$J$2:$J$301,11) -> 72704 | Y12: =INDEX(Posts!$L$2:$L$301, MATCH(X12, $X$2:$X$301, 0)) -> #SoundtrackOfLife | AA12: #NowPlaying | AB12: 26701
A13: =(Posts!F13+Posts!G13+Posts!H13) -> 2082 | B13: =('Engagement Analysis'!A13)/Posts!I13 -> 0.054191936 | G13: Top 10 Post By Engagement Rate | X13: =LARGE(Posts!$J$2:$J$301,12) -> 72595 | Y13: =INDEX(Posts!$L$2:$L$301, MATCH(X13, $X$2:$X$301, 0)) -> #SoundtrackOfLife,#NowPlaying | AA13: #SoundtrackOfLife | AB13: 20978
A14: =(Posts!F14+Posts!G14+Posts!H14) -> 4336 | B14: =('Engagement Analysis'!A14)/Posts!I14 -> 0.074550394 | G14: Formula= LARGE(array, k) | H14: INDEX(return_range, MATCH(lookup_value, lookup_range, 0)) | X14: =LARGE(Posts!$J$2:$J$301,13) -> 72573 | Y14: =INDEX(Posts!$L$2:$L$301, MATCH(X14, $X$2:$X$301, 0)) -> #MusicForEveryone,#NowPlaying | AA14: #SpotifyWrapped | AB14: 7088
A15: =(Posts!F15+Posts!G15+Posts!H15) -> 3122 | B15: =('Engagement Analysis'!A15)/Posts!I15 -> 0.085063484 | X15: =LARGE(Posts!$J$2:$J$301,14) -> 72428 | Y15: =INDEX(Posts!$L$2:$L$301, MATCH(X15, $X$2:$X$301, 0)) -> #NowPlaying | AA15: Total | AB15: =SUM(AB10:AB14) -> 92692
A16: =(Posts!F16+Posts!G16+Posts!H16) -> 4227 | B16: =('Engagement Analysis'!A16)/Posts!I16 -> 0.11274405 | X16: =LARGE(Posts!$J$2:$J$301,15) -> 72110 | Y16: =INDEX(Posts!$L$2:$L$301, MATCH(X16, $X$2:$X$301, 0)) -> #NowPlaying
A17: =(Posts!F17+Posts!G17+Posts!H17) -> 4520 | B17: =('Engagement Analysis'!A17)/Posts!I17 -> 0.093810967 | AA17: Average Clicks per post by Hashtag
A18: =(Posts!F18+Posts!G18+Posts!H18) -> 1953 | B18: =('Engagement Analysis'!A18)/Posts!I18 -> 0.04721497 | X18: LARGE(array, k) | Y18: INDEX(return_range, MATCH(lookup_value, lookup_range, 0))
A19: =(Posts!F19+Posts!G19+Posts!H19) -> 4545 | B19: =('Engagement Analysis'!A19)/Posts!I19 -> 0.14080798
A20: =(Posts!F20+Posts!G20+Posts!H20) -> 2045 | B20: =('Engagement Analysis'!A20)/Posts!I20 -> 0.06425564 | X20: Top Performing hashtags
A21: =(Posts!F21+Posts!G21+Posts!H21) -> 4472 | B21: =('Engagement Analysis'!A21)/Posts!I21 -> 0.15347656
A22: =(Posts!F22+Posts!G22+Posts!H22) -> 2424 | B22: =('Engagement Analysis'!A22)/Posts!I22 -> 0.043543867
A23: =(Posts!F23+Posts!G23+Posts!H23) -> 5595 | B23: =('Engagement Analysis'!A23)/Posts!I23 -> 0.19548583
A24: =(Posts!F24+Posts!G24+Posts!H24) -> 3362 | B24: =('Engagement Analysis'!A24)/Posts!I24 -> 0.080047619
A25: =(Posts!F25+Posts!G25+Posts!H25) -> 3166 | B25: =('Engagement Analysis'!A25)/Posts!I25 -> 0.11026748
A26: =(Posts!F26+Posts!G26+Posts!H26) -> 4425 | B26: =('Engagement Analysis'!A26)/Posts!I26 -> 0.081036535
A27: =(Posts!F27+Posts!G27+Posts!H27) -> 2861 | B27: =('Engagement Analysis'!A27)/Posts!I27 -> 0.051734114
A28: =(Posts!F28+Posts!G28+Posts!H28) -> 3523 | B28: =('Engagement Analysis'!A28)/Posts!I28 -> 0.1136305
A29: =(Posts!F29+Posts!G29+Posts!H29) -> 4071 | B29: =('Engagement Analysis'!A29)/Posts!I29 -> 0.08205676
A30: =(Posts!F30+Posts!G30+Posts!H30) -> 3993 | B30: =('Engagement Analysis'!A30)/Posts!I30 -> 0.069526911
A31: =(Posts!F31+Posts!G31+Posts!H31) -> 2773 | B31: =('Engagement Analysis'!A31)/Posts!I31 -> 0.103994
A32: =(Posts!F32+Posts!G32+Posts!H32) -> 4530 | B32: =('Engagement Analysis'!A32)/Posts!I32 -> 0.080484685
... A301: =(Posts!F301+Posts!G301+Posts!H301) -> 2712 | B301: =('Engagement Analysis'!A301)/Posts!I301 -> 0.094300914

Sheet Platform Performance Analysis
A1: Highest Engagement Platform | B1: Platform | C1: Sum of Growth rate per post | E1: Platform | F1: Average of Engagement_Rate | G1: Sum of Ad_Spend | I1: Platform Recommendation
A2: =INDEX(Posts!B2:B301, MATCH(MAX('Engagement Analysis'!B2:B301),'Engagement Analysis'!B2:B301, 0)) -> Twitter | B2: Instagram | C2: 0.2914909 | E2: Instagram | F2: 6.458209 | G2: 1035942 | I2: Twitter | K2: Instagram
B3: Twitter | C3: 0.31489507 | E3: Twitter | F3: 6.8856716 | G3: 1114204 | I3: Highest Engement rate | J3: 0.096034606 | K3: Highest Engement rate | L3: 0.09079483
A4: Formula = INDEX(return_range, MATCH(lookup_value, lookup_range, 0)) | B4: YouTube | C4: 0.26067101 | E4: YouTube | F4: 6.7189394 | G4: 1065782 | I4: Highest Likes, Shares & comments | J4: 516611 | K4: Highest Likes, Shares & comments | L4: 301576
B5: Grand Total | C5: 0.86705698 | E5: Grand Total | F5: 6.68745 | G5: 3215928 | I5: Highest of No of Reach | J5: =SUMIF(Posts!B2:B301,"Twitter",Posts!J2:J301) -> 6549147 | K5: Highest of No of Reach | L5: =SUMIF(Posts!B2:B301,"Instagram",Posts!J2:J301) -> 4221099
A6: Highest Engagement Platform | I6: Highest of no Hashtags | J6: 148 | K6: Highest of no Hashtags | L6: =COUNTIFS(Posts!B2:B301,"Instagram",Posts!L2:L301,"*") -> 89
K7: Budget | L7: 1035942
I9: Recommending Twitter & Instagram to Continue Maximum Engagement & Growth
E24: Weekly AverageEngagement & Ad spend Distribution Chart
B25: Columns used: Ad spend & Enagement rate = F&G
B26: Growth rate per post = New followers - Unfollows / Total Followers
B28: Weekly Growth rate across platform

Sheet  Hashtag & Content Strategy 
A1: Engagement Rate Column | G1: impressiom/total flower
A2: =(Posts!F2+Posts!G2+Posts!H2)/Posts!I2 -> 0.1320051 | C2: Hashtags | D2: Count of Hashtags Used | E2: Average of engagement rate | G2: =Posts!I2/'Engagement Summary'!E3 -> 0.092916239
A3: =(Posts!F3+Posts!G3+Posts!H3)/Posts!I3 -> 0.087095335 | C3: #DiscoverWeekly | D3: 33 | E3: 0.090257921 | G3: =Posts!I3/'Engagement Summary'!E4 -> 0.078675569 | H3: Count of engagement rate | I3: Column Labels | N3: Instagram for Text | O3: =COUNTIFS(Posts!B2:B301,"Instagram",Posts!D2:D301,"Text") -> 66
A4: =(Posts!F4+Posts!G4+Posts!H4)/Posts!I4 -> 0.070477353 | C4: #DiscoverWeekly,#MusicForEveryone | D4: 34 | E4: 0.084104102 | G4: =Posts!I4/'Engagement Summary'!E5 -> 0.51401475 | H4: content types | I4: Instagram | J4: Twitter | K4: YouTube | L4: Grand Total | N4: Twitter for Story | O4: =COUNTIFS(Posts!B2:B301,"Twitter",Posts!D2:D301,"Story") -> 87
A5: =(Posts!F5+Posts!G5+Posts!H5)/Posts!I5 -> 0.12157141 | C5: #DiscoverWeekly,#SoundtrackOfLife | D5: 29 | E5: 0.090106882 | G5: =Posts!I5/'Engagement Summary'!E6 -> 0.090008574 | H5: Reel | K5: 29 | L5: 29 | N5: YouTube for Reel | O5: =COUNTIFS(Posts!B2:B301,"*YouTube*",Posts!D2:D301,"*Reel*") -> 29
A6: =(Posts!F6+Posts!G6+Posts!H6)/Posts!I6 -> 0.13147002 | C6: #DiscoverWeekly,#SpotifyWrapped | D6: 34 | E6: 0.086403291 | G6: =Posts!I6/'Engagement Summary'!E7 -> 0.06230769 | H6: Story | I6: 23 | J6: 87 | L6: 110
A7: =(Posts!F7+Posts!G7+Posts!H7)/Posts!I7 -> 0.074828079 | C7: #MusicForEveryone,#NowPlaying | D7: 33 | E7: 0.094160898 | G7: =Posts!I7/'Engagement Summary'!E8 -> 0.61269229 | H7: Text | I7: 66 | J7: 61 | K7: 34 | L7: 161 | N7: Recommendation of Content type & Platforms
A8: =(Posts!F8+Posts!G8+Posts!H8)/Posts!I8 -> 0.26064752 | C8: #NowPlaying | D8: 57 | E8: 0.099415714 | G8: =Posts!I8/'Engagement Summary'!E9 -> 0.084392166 | H8: Grand Total | I8: 89 | J8: 148 | K8: 63 | L8: 300
A9: =(Posts!F9+Posts!G9+Posts!H9)/Posts!I9 -> 0.087100435 | C9: #SoundtrackOfLife | D9: 27 | E9: 0.087432153 | G9: =Posts!I9/'Engagement Summary'!E10 -> 0.084447426
A10: =(Posts!F10+Posts!G10+Posts!H10)/Posts!I10 -> 0.083943337 | C10: #SoundtrackOfLife,#NowPlaying | D10: 53 | E10: 0.10039882 | G10: =Posts!I10/'Engagement Summary'!E11 -> 0.67689767 | H10: Content types wise performance across platforms | N10: COUNTIFS(Posts!B2:B301,"Twitter",Posts!D2:D301,"Story")
A11: =(Posts!F11+Posts!G11+Posts!H11)/Posts!I11 -> 0.12997311 | C11: Grand Total | D11: 300 | E11: 0.092815577 | G11: =Posts!I11/'Engagement Summary'!E12 -> 0.16767221
A12: =(Posts!F12+Posts!G12+Posts!H12)/Posts!I12 -> 0.084525482 | G12: =Posts!I12/'Engagement Summary'!E13 -> 0.2485101 | H12: Tables used Platform, Engagement Rate & Content type
A13: =(Posts!F13+Posts!G13+Posts!H13)/Posts!I13 -> 0.054191936 | C13: Most frequent hashtags and average engagement for each | G13: =Posts!I13/'Engagement Summary'!E14 -> 0.21509392
A14: =(Posts!F14+Posts!G14+Posts!H14)/Posts!I14 -> 0.074550394 | G14: =Posts!I14/'Engagement Summary'!E15 -> 0.26651942
A15: =(Posts!F15+Posts!G15+Posts!H15)/Posts!I15 -> 0.085063484 | G15: =Posts!I15/'Engagement Summary'!E16 -> 0.12217832
A16: =(Posts!F16+Posts!G16+Posts!H16)/Posts!I16 -> 0.11274405 | G16: =Posts!I16/'Engagement Summary'!E17 -> 0.11023136
A17: =(Posts!F17+Posts!G17+Posts!H17)/Posts!I17 -> 0.093810967 | G17: =Posts!I17/'Engagement Summary'!E18 -> 0.62683111
A18: =(Posts!F18+Posts!G18+Posts!H18)/Posts!I18 -> 0.04721497 | G18: =Posts!I18/'Engagement Summary'!E19 -> 0.21417587
A19: =(Posts!F19+Posts!G19+Posts!H19)/Posts!I19 -> 0.14080798 | G19: =Posts!I19/'Engagement Summary'!E20 -> 0.19024548
A20: =(Posts!F20+Posts!G20+Posts!H20)/Posts!I20 -> 0.06425564 | G20: =Posts!I20/'Engagement Summary'!E21 -> 0.12067691
A21: =(Posts!F21+Posts!G21+Posts!H21)/Posts!I21 -> 0.15347656 | G21: =Posts!I21/'Engagement Summary'!E22 -> 0.14081703
A22: =(Posts!F22+Posts!G22+Posts!H22)/Posts!I22 -> 0.043543867 | G22: =Posts!I22/'Engagement Summary'!E23 -> 0.27272059
A23: =(Posts!F23+Posts!G23+Posts!H23)/Posts!I23 -> 0.19548583 | G23: =Posts!I23/'Engagement Summary'!E24 -> 0.10745635
A24: =(Posts!F24+Posts!G24+Posts!H24)/Posts!I24 -> 0.080047619 | G24: =Posts!I24/'Engagement Summary'!E25 -> 0.11035034
A25: =(Posts!F25+Posts!G25+Posts!H25)/Posts!I25 -> 0.11026748 | G25: =Posts!I25/'Engagement Summary'!E26 -> 0.076289065
... A200: =(Posts!F200+Posts!G200+Posts!H200)/Posts!I200 -> 0.13946228 | G200: =Posts!I200/'Engagement Summary'!E201 -> 0.094615213
A201: =(Posts!F201+Posts!G201+Posts!H201)/Posts!I201 -> 0.045247824
A202: =(Posts!F202+Posts!G202+Posts!H202)/Posts!I202 -> 0.062974139
A203: =(Posts!F203+Posts!G203+Posts!H203)/Posts!I203 -> 0.10784235
A204: =(Posts!F204+Posts!G204+Posts!H204)/Posts!I204 -> 0.082690259
A205: =(Posts!F205+Posts!G205+Posts!H205)/Posts!I205 -> 0.097836889
A206: =(Posts!F206+Posts!G206+Posts!H206)/Posts!I206 -> 0.077428927
A207: =(Posts!F207+Posts!G207+Posts!H207)/Posts!I207 -> 0.079782522
A208: =(Posts!F208+Posts!G208+Posts!H208)/Posts!I208 -> 0.071022341
A209: =(Posts!F209+Posts!G209+Posts!H209)/Posts!I209 -> 0.039319108
A210: =(Posts!F210+Posts!G210+Posts!H210)/Posts!I210 -> 0.077181742
A211: =(Posts!F211+Posts!G211+Posts!H211)/Posts!I211 -> 0.034110398
A212: =(Posts!F212+Posts!G212+Posts!H212)/Posts!I212 -> 0.031623578
... A301: =(Posts!F301+Posts!G301+Posts!H301)/Posts!I301 -> 0.094300914

Sheet Campaign Effectiveness 
A1: Campaign_Name | B1: Total of impressions, likes, clicks | C1: Campaign Name | D1: Sum of Total of impressions, likes, clicks | F1: Campaign Name | G1: Average of impressions, likes, clicks | I1: Campaign_Name | J1: Platform | K1: Engagement_Rate % | L1: J/100 | M1: Ad_Spend | N1: RIO | O1: Highest ROI Campaign | Q1: Highest Growth rate | R1: Highest follower Maintained after unfollows | S1: Strong follower Week start date | T1: Stongest Follower Campaign
A2: ChillVibes | B2: =(Posts!F2+Posts!I2+Posts!K2) -> 23728 | C2: ChillVibes | D2: 6831610 | F2: ChillVibes | G2: =AVERAGEIF(A2:A301,"ChillVibes",B2:B301) -> 44361.104 | I2: ChillVibes | J2: Instagram | K2: 9.92 | L2: =K2*100 -> 992 | M2: 23125 | N2: =L2/M2 -> 0.042897297 | O2: =INDEX(I2:I301, MATCH(MAX(N2:N201), N2:N201, 0 )) -> ChillVibes | Q2: =MAX('Engagement Summary'!H2:H201) -> 0.017836234 | R2: =MAX('Engagement Summary'!I2:I201) -> 1397 | S2: =INDEX('Engagement Summary'!A2:A201,MATCH(MAX('Engagement Summary'!E2:E201),'Engagement Summary'!E2:E201,0)) -> 45740 | T2: IndieWave
A3: IndieWave | B3: =(Posts!F3+Posts!I3+Posts!K3) -> 31336 | C3: IndieWave | D3: 4332477 | F3: IndieWave | G3: =AVERAGEIF(A2:A301,"IndieWave",B2:B301) -> 46090.181 | I3: IndieWave | J3: Twitter | K3: 8.05 | L3: =K3*100 -> 805 | M3: 22788 | N3: =L3/M3 -> 0.03532561
A4: ChillVibes | B4: =(Posts!F4+Posts!I4+Posts!K4) -> 50746 | C4: SummerBeats | D4: 1329281 | F4: Wrapped2024 | G4: =AVERAGEIF(A2:A301,"Wrapped2024",B2:B301) -> 40514.565 | I4: ChillVibes | J4: YouTube | K4: 7.72 | L4: =K4*100 -> 772 | M4: 7810 | N4: =L4/M4 -> 0.098847631 | O4: Formula=INDEX(Campaign name column, MATCH(MAX(RIO-column range), RIO-column:range, 0 )) | Q4: Strongest Follower Campaign = IndieWave
A5: ChillVibes | B5: =(Posts!F5+Posts!I5+Posts!K5) -> 33049 | C5: Wrapped2024 | D5: 931835 | F5: IndieWave | G5: =F10:G10=AVERAGEIF(A2:A301,"IndieWave",B2:B301) -> FALSE | I5: ChillVibes | J5: Instagram | K5: 9.4 | L5: =K5*100 -> 940 | M5: 11966 | N5: =L5/M5 -> 0.078555908
A6: IndieWave | B6: =(Posts!F6+Posts!I6+Posts!K6) -> 27349 | C6: Grand Total | D6: 13425203 | F6: Total | G6: =SUM(G2+G3+G4+G5) -> 130965.85 | I6: IndieWave | J6: Twitter | K6: 9.02 | L6: =K6*100 -> 902 | M6: 26298 | N6: =L6/M6 -> 0.034299186
A7: IndieWave | B7: =(Posts!F7+Posts!I7+Posts!K7) -> 62779 | I7: IndieWave | J7: YouTube | K7: 9.96 | L7: =K7*100 -> 996 | M7: 22029 | N7: =L7/M7 -> 0.045213128
A8: ChillVibes | B8: =(Posts!F8+Posts!I8+Posts!K8) -> 25642 | C8: Total count of impressions, likes, clicks as per campaign | F8: Average of impressions, likes, clicks as per campaign | I8: ChillVibes | J8: Instagram | K8: 5.29 | L8: =K8*100 -> 529 | M8: 12391 | N8: =L8/M8 -> 0.042692277 | Q8: MAX('Engagement Summary'!(Growth rate per post- range) | R8: INDEX('Engagement Summary'!(Week start date range),MATCH(MAX('Engagement Summary'!(Total Followers range ),'Engagement Summary'!Total followers column range,0))
A9: ChillVibes | B9: =(Posts!F9+Posts!I9+Posts!K9) -> 22696 | I9: ChillVibes | J9: Twitter | K9: 8.3 | L9: =K9*100 -> 830 | M9: 14477 | N9: =L9/M9 -> 0.05733232
A10: ChillVibes | B10: =(Posts!F10+Posts!I10+Posts!K10) -> 63619 | C10: Tables used Campaign name & Total of impression,clicks, likes | F10: Formula=AVERAGEIF(Campaign column,"Campaign name",Total of impression/likes/clicks) | I10: ChillVibes | J10: YouTube | K10: 4.66 | L10: =K10*100 -> 466 | M10: 25040 | N10: =L10/M10 -> 0.018610224
A11: ChillVibes | B11: =(Posts!F11+Posts!I11+Posts!K11) -> 24207 | I11: ChillVibes | J11: Instagram | K11: 9.48 | L11: =K11*100 -> 948 | M11: 22619 | N11: =L11/M11 -> 0.041911667
A12: IndieWave | B12: =(Posts!F12+Posts!I12+Posts!K12) -> 33375 | I12: IndieWave | J12: Twitter | K12: 7.11 | L12: =K12*100 -> 711 | M12: 12399 | N12: =L12/M12 -> 0.057343334
A13: ChillVibes | B13: =(Posts!F13+Posts!I13+Posts!K13) -> 39990 | I13: ChillVibes | J13: YouTube | K13: 9.65 | L13: =K13*100 -> 965 | M13: 22456 | N13: =L13/M13 -> 0.042972925
A14: ChillVibes | B14: =(Posts!F14+Posts!I14+Posts!K14) -> 62331 | I14: ChillVibes | J14: Instagram | K14: 5.43 | L14: =K14*100 -> 543 | M14: 19328 | N14: =L14/M14 -> 0.028093957
A15: ChillVibes | B15: =(Posts!F15+Posts!I15+Posts!K15) -> 39426 | I15: ChillVibes | J15: Twitter | K15: 4.52 | L15: =K15*100 -> 452 | M15: 21107 | N15: =L15/M15 -> 0.021414697
A16: ChillVibes | B16: =(Posts!F16+Posts!I16+Posts!K16) -> 41147 | I16: ChillVibes | J16: YouTube | K16: 4.33 | L16: =K16*100 -> 433 | M16: 12277 | N16: =L16/M16 -> 0.035269203
A17: ChillVibes | B17: =(Posts!F17+Posts!I17+Posts!K17) -> 52403 | I17: ChillVibes | J17: Instagram | K17: 8.52 | L17: =K17*100 -> 852 | M17: 11684 | N17: =L17/M17 -> 0.072920233
A18: ChillVibes | B18: =(Posts!F18+Posts!I18+Posts!K18) -> 42961 | I18: ChillVibes | J18: Twitter | K18: 8.55 | L18: =K18*100 -> 855 | M18: 14412 | N18: =L18/M18 -> 0.059325562
A19: Wrapped2024 | B19: =(Posts!F19+Posts!I19+Posts!K19) -> 36794 | I19: Wrapped2024 | J19: YouTube | K19: 7.99 | L19: =K19*100 -> 799 | M19: 15924 | N19: =L19/M19 -> 0.050175835
A20: SummerBeats | B20: =(Posts!F20+Posts!I20+Posts!K20) -> 33672 | I20: SummerBeats | J20: Instagram | K20: 6.31 | L20: =K20*100 -> 631 | M20: 12390 | N20: =L20/M20 -> 0.050928168
A21: IndieWave | B21: =(Posts!F21+Posts!I21+Posts!K21) -> 32981 | I21: IndieWave | J21: Twitter | K21: 8.53 | L21: =K21*100 -> 853 | M21: 25742 | N21: =L21/M21 -> 0.033136508
A22: Wrapped2024 | B22: =(Posts!F22+Posts!I22+Posts!K22) -> 57576 | I22: Wrapped2024 | J22: YouTube | K22: 8.42 | L22: =K22*100 -> 842 | M22: 10495 | N22: =L22/M22 -> 0.08022868
... A201: ChillVibes | B201: =(Posts!F201+Posts!I201+Posts!K201) -> 58519 | I201: ChillVibes | J201: Twitter | K201: 5.12 | L201: =K201*100 -> 512 | M201: 11418 | N201: =L201/M201 -> 0.044841478
A202: ChillVibes | B202: =(Posts!F202+Posts!I202+Posts!K202) -> 37412 | I202: ChillVibes | L202: =K202*100 -> 0
A203: ChillVibes | B203: =(Posts!F203+Posts!I203+Posts!K203) -> 27413 | I203: ChillVibes | L203: =K203*100 -> 0
A204: IndieWave | B204: =(Posts!F204+Posts!I204+Posts!K204) -> 33162 | I204: IndieWave | L204: =K204*100 -> 0
A205: ChillVibes | B205: =(Posts!F205+Posts!I205+Posts!K205) -> 51739 | I205: ChillVibes | L205: =K205*100 -> 0
A206: IndieWave | B206: =(Posts!F206+Posts!I206+Posts!K206) -> 58501 | I206: IndieWave | L206: =K206*100 -> 0
A207: ChillVibes | B207: =(Posts!F207+Posts!I207+Posts!K207) -> 61780 | I207: ChillVibes | L207: =K207*100 -> 0
A208: ChillVibes | B208: =(Posts!F208+Posts!I208+Posts!K208) -> 54531 | I208: ChillVibes | L208: =K208*100 -> 0
A209: IndieWave | B209: =(Posts!F209+Posts!I209+Posts!K209) -> 55865 | I209: IndieWave | L209: =K209*100 -> 0
A210: ChillVibes | B210: =(Posts!F210+Posts!I210+Posts!K210) -> 47202 | I210: ChillVibes | L210: =K210*100 -> 0
A211: ChillVibes | B211: =(Posts!F211+Posts!I211+Posts!K211) -> 48514 | I211: ChillVibes | L211: =K211*100 -> 0
A212: ChillVibes | B212: =(Posts!F212+Posts!I212+Posts!K212) -> 49877 | I212: ChillVibes | L212: =K212*100 -> 0
A213: ChillVibes | B213: =(Posts!F213+Posts!I213+Posts!K213) -> 56270 | I213: ChillVibes | L213: =K213*100 -> 0
... A301: ChillVibes | B301: =(Posts!F301+Posts!I301+Posts!K301) -> 30912 | I301: ChillVibes | L301: =K301*100 -> 0

Sheet Follower Retention & Loyalty
A1: Ad_Spend | B1: Net Gain | C1: Weeks date | D1: Follower Net Gain Per week | E1: Max Net follower Gain count | F1: Week with highest net follower gain | H1: Weeks Date | I1: Weekly Net Gain | J1: Months | K1: Average of Net gain | U1: Weeks | V1: Total Net Follower Gain | W1: Ad Spent
A2: 23125 | B2: ='Engagement Summary'!C2-'Engagement Summary'!D2 -> 1334 | C2: 45446 | D2: 3419 | E2: =MAX(D2:D68) -> 3576 | F2: =INDEX(C2:C68, MATCH(MAX(D2:D68), D2:D68, 0)) -> 45600 | H2: 45446 | I2: 3419 | J2: 45444 | K2: =AVERAGE(I2:I5) -> 2951 | U2: 45446 | V2: 3419 | W2: 53723
A3: 22788 | B3: ='Engagement Summary'!C3-'Engagement Summary'!D3 -> 909 | C3: 45453 | D3: 2777 | E3: Formula= MAX( Follower net gain per week column range) | F3: INDEX(Weeks Date Column range (C)), MATCH(MAX(Follower net gain column -(D)), (D), 0)) | H3: 45453 | I3: 2777 | J3: 45474 | K3: =AVERAGE(I6:I10) -> 2472.6 | U3: 45453 | V3: 2777 | W3: 60293
A4: 7810 | B4: ='Engagement Summary'!C4-'Engagement Summary'!D4 -> 1176 | C4: 45460 | D4: 3175 | H4: 45460 | I4: 3175 | J4: 45505 | K4: =AVERAGE(I11:I14) -> 2628.75 | U4: 45460 | V4: 3175 | W4: 51908
A5: 11966 | B5: ='Engagement Summary'!C5-'Engagement Summary'!D5 -> 928 | C5: 45467 | D5: 2433 | H5: 45467 | I5: 2433 | J5: 45536 | K5: =AVERAGE(I15:I19) -> 2646 | U5: 45467 | V5: 2433 | W5: 57474
A6: 26298 | B6: ='Engagement Summary'!C6-'Engagement Summary'!D6 -> 1397 | C6: 45474 | D6: 2426 | H6: 45474 | I6: 2426 | J6: 45566 | K6: =AVERAGE(I20:I23) -> 2495.25 | U6: 45474 | V6: 2426 | W6: 52712
A7: 22029 | B7: ='Engagement Summary'!C7-'Engagement Summary'!D7 -> 452 | C7: 45481 | D7: 3155 | E7: Weeks with Highest Net Follower Gain | H7: 45481 | I7: 3155 | J7: 45597 | K7: =AVERAGE(I24:I27) -> 2648 | U7: 45481 | V7: 3155 | W7: 42020
A8: 12391 | B8: ='Engagement Summary'!C8-'Engagement Summary'!D8 -> 590 | C8: 45488 | D8: 2369 | H8: 45488 | I8: 2369 | J8: 45627 | K8: =AVERAGE(I28:I32) -> 2272.2 | U8: 45488 | V8: 2369 | W8: 48627
A9: 14477 | B9: ='Engagement Summary'!C9-'Engagement Summary'!D9 -> 1283 | C9: 45495 | D9: 2281 | H9: 45495 | I9: 2281 | J9: 45658 | K9: =AVERAGE(I33:I36) -> 2138 | U9: 45495 | V9: 2281 | W9: 48009
A10: 25040 | B10: ='Engagement Summary'!C10-'Engagement Summary'!D10 -> 1302 | C10: 45502 | D10: 2132 | H10: 45502 | I10: 2132 | J10: 45689 | K10: =AVERAGE(I37:I40) -> 1824.25 | U10: 45502 | V10: 2132 | W10: 34912
A11: 22619 | B11: ='Engagement Summary'!C11-'Engagement Summary'!D11 -> 612 | C11: 45509 | D11: 2693 | H11: 45509 | I11: 2693 | J11: 45717 | K11: =AVERAGE(I41:I45) -> 2545.2 | U11: 45509 | V11: 2693 | W11: 45349
A12: 12399 | B12: ='Engagement Summary'!C12-'Engagement Summary'!D12 -> 1121 | C12: 45516 | D12: 3072 | H12: 45516 | I12: 3072 | J12: 45748 | K12: =AVERAGE(I46:I49) -> 2653.25 | U12: 45516 | V12: 3072 | W12: 24209
A13: 22456 | B13: ='Engagement Summary'!C13-'Engagement Summary'!D13 -> 700 | C13: 45523 | D13: 2300 | H13: 45523 | I13: 2300 | J13: 45778 | K13: =AVERAGE(I50:I53) -> 2483 | U13: 45523 | V13: 2300 | W13: 52127
A14: 19328 | B14: ='Engagement Summary'!C14-'Engagement Summary'!D14 -> 714 | C14: 45530 | D14: 2450 | H14: 45530 | I14: 2450 | J14: 45809 | K14: =AVERAGE(I54:I58) -> 2001.6 | U14: 45530 | V14: 2450 | W14: 66319
A15: 21107 | B15: ='Engagement Summary'!C15-'Engagement Summary'!D15 -> 595 | C15: 45537 | D15: 2502 | H15: 45537 | I15: 2502 | J15: 45839 | K15: =AVERAGE(I59:I62) -> 2813.25 | U15: 45537 | V15: 2502 | W15: 55150
A16: 12277 | B16: ='Engagement Summary'!C16-'Engagement Summary'!D16 -> 1117 | C16: 45544 | D16: 2630 | H16: 45544 | I16: 2630 | J16: 45870 | K16: =AVERAGE(I63:I66) -> 2125.25 | U16: 45544 | V16: 2630 | W16: 44141
A17: 11684 | B17: ='Engagement Summary'!C17-'Engagement Summary'!D17 -> 667 | C17: 45551 | D17: 2162 | H17: 45551 | I17: 2162 | J17: 45901 | K17: =AVERAGE(I67:I68) -> 1430 | U17: 45551 | V17: 2162 | W17: 51007
A18: 14412 | B18: ='Engagement Summary'!C18-'Engagement Summary'!D18 -> 1371 | C18: 45558 | D18: 2785 | H18: 45558 | I18: 2785 | J18: Formula = AVERAGE(Weekly Net gain - I Column) | U18: 45558 | V18: 2785 | W18: 61088
A19: 15924 | B19: ='Engagement Summary'!C19-'Engagement Summary'!D19 -> 1117 | C19: 45565 | D19: 3151 | H19: 45565 | I19: 3151 | M19: Moving Average Chart for Follwer Trends | U19: 45565 | V19: 3151 | W19: 47808
A20: 12390 | B20: ='Engagement Summary'!C20-'Engagement Summary'!D20 -> 359 | C20: 45572 | D20: 2338 | H20: 45572 | I20: 2338 | U20: 45572 | V20: 2338 | W20: 40791
A21: 25742 | B21: ='Engagement Summary'!C21-'Engagement Summary'!D21 -> 1098 | C21: 45579 | D21: 2670 | H21: 45579 | I21: 2670 | U21: 45579 | V21: 2670 | W21: 42137
A22: 10495 | B22: ='Engagement Summary'!C22-'Engagement Summary'!D22 -> 912 | C22: 45586 | D22: 2792 | H22: 45586 | I22: 2792 | U22: 45586 | V22: 2792 | W22: 52390
A23: 7797 | B23: ='Engagement Summary'!C23-'Engagement Summary'!D23 -> 792 | C23: 45593 | D23: 2181 | H23: 45593 | I23: 2181 | U23: 45593 | V23: 2181 | W23: 75610
A24: 15595 | B24: ='Engagement Summary'!C24-'Engagement Summary'!D24 -> 364 | C24: 45600 | D24: 3576 | H24: 45600 | I24: 3576 | U24: 45600 | V24: 3576 | W24: 51694
A25: 24617 | B25: ='Engagement Summary'!C25-'Engagement Summary'!D25 -> 1125 | C25: 45607 | D25: 2794 | H25: 45607 | I25: 2794 | U25: 45607 | V25: 2794 | W25: 51792 | Y25: Ad Spend vs. Follower Growth
A26: 9847 | B26: ='Engagement Summary'!C26-'Engagement Summary'!D26 -> 869 | C26: 45614 | D26: 1935 | H26: 45614 | I26: 1935 | U26: 45614 | V26: 1935 | W26: 40181
A27: 13644 | B27: ='Engagement Summary'!C27-'Engagement Summary'!D27 -> 414 | C27: 45621 | D27: 2287 | H27: 45621 | I27: 2287 | U27: 45621 | V27: 2287 | W27: 35823
A28: 11421 | B28: ='Engagement Summary'!C28-'Engagement Summary'!D28 -> 849 | C28: 45628 | D28: 2383 | H28: 45628 | I28: 2383 | U28: 45628 | V28: 2383 | W28: 45124
A29: 15613 | B29: ='Engagement Summary'!C29-'Engagement Summary'!D29 -> 1353 | C29: 45635 | D29: 1398 | H29: 45635 | I29: 1398 | U29: 45635 | V29: 1398 | W29: 59678
A30: 23900 | B30: ='Engagement Summary'!C30-'Engagement Summary'!D30 -> 582 | C30: 45642 | D30: 2693 | H30: 45642 | I30: 2693 | U30: 45642 | V30: 2693 | W30: 51493
A31: 5836 | B31: ='Engagement Summary'!C31-'Engagement Summary'!D31 -> 758 | C31: 45649 | D31: 2550 | H31: 45649 | I31: 2550 | U31: 45649 | V31: 2550 | W31: 42747
A32: 5624 | B32: ='Engagement Summary'!C32-'Engagement Summary'!D32 -> 977 | C32: 45656 | D32: 2337 | H32: 45656 | I32: 2337 | U32: 45656 | V32: 2337 | W32: 44785
A33: 10311 | B33: ='Engagement Summary'!C33-'Engagement Summary'!D33 -> 1191 | C33: 45663 | D33: 2451 | H33: 45663 | I33: 2451 | U33: 45663 | V33: 2451 | W33: 34533
A34: 8274 | B34: ='Engagement Summary'!C34-'Engagement Summary'!D34 -> 904 | C34: 45670 | D34: 2341 | H34: 45670 | I34: 2341 | U34: 45670 | V34: 2341 | W34: 27644
A35: 6031 | B35: ='Engagement Summary'!C35-'Engagement Summary'!D35 -> 909 | C35: 45677 | D35: 1832 | H35: 45677 | I35: 1832 | U35: 45677 | V35: 1832 | W35: 42348
A36: 27829 | B36: ='Engagement Summary'!C36-'Engagement Summary'!D36 -> 382 | C36: 45684 | D36: 1928 | H36: 45684 | I36: 1928 | U36: 45684 | V36: 1928 | W36: 37127
A37: 18267 | B37: ='Engagement Summary'!C37-'Engagement Summary'!D37 -> 1009 | C37: 45691 | D37: 1680 | H37: 45691 | I37: 1680 | U37: 45691 | V37: 1680 | W37: 56414
... A68: 14563 | B68: ='Engagement Summary'!C68-'Engagement Summary'!D68 -> 1202 | C68: 45908 | D68: 1436 | H68: 45908 | I68: 1436 | U68: 45908 | V68: 1436 | W68: 19299
A69: 26273 | B69: ='Engagement Summary'!C69-'Engagement Summary'!D69 -> 1390 | C69: Grand Total | D69: 161588 | H69: Grand Total | I69: 161588 | U69: Grand Total | V69: 161588 | W69: 3215928
A70: 10858 | B70: ='Engagement Summary'!C70-'Engagement Summary'!D70 -> 984
...

Sheet Summary
B1: Marketing Strategies
A2: 1 | B2: Prioritize Twitter & Instagram because of their Highest Engagement rate (9 - 9.6%) & Maximum Growth rate 31% & 29% respectively
A3: 2 | B3: Allocate the budget on Good performing Platforms, For Twitter can continue the existing budget, May reduce the budget of YouTube (Engagement rate = 8.8%) & allocate to Instagram as its performing Better (Engagement rate = 9.06%)
A4: 3 | B4: Look for the Weeks that has Highest Net follower gain & Try to consider it as peak time. Plan for those timeline to achieve more engagement. like currently (4-11-2024) Seen the highest followers. so we can do more campaign in these specific periods.
B6: Campaign Planning
A7: 4 | B7: Focus on Campaign like ChillVibes which has Highest no of Engagement among others Similarly Spend on campaigns like IndieWave which has Max Average Interaction.
A8: 5 | B8: Step up the Budget for ChillVibes because of its Highest Retuns.
A9: 6 | B9: Continue & Strongly promote IndieWave Campaign as it has Stronger Follwers.
B11: Content Performance
A12: 7 | B12: Focus More on top Performing Hashtags to keep on engaging with User.
A13: 8 | B13: Promote Story content type on Twitter to get maximum Engagement & similarly Text Content on Instagram, as these both content types are having max engagement across platforms.
A14: 9 | B14: Focus on Twitter & Instagram platforms for the different Content posting.
A15: 10 | B15: Make Sure to Follow Best Combination of Content types with Platform like Currently as per data we should focus on Story for Twitter & Instagram for Text Content.
B17: Platform Specific ROI
A18: 11 | B18: Twitter is the Platform where we are getting maximum Return on investment, so we should promote this platform for the better reach with users.
B20: https://screenrec.com/share/iYVb6lhPBN | C20: Video Link
B21: https://drive.google.com/file/d/13H8FVNRhgeCwHEIM-O0O2P14KXxwhEgS/view?usp=sharing | C21: Alternate link
